<?xml version="1.0"?>
<!--
Robotiq 2F-85 Gripper URDF Macro for ROS2 Humble
Adapted from IFRA Cranfield ros2_SimRealRobotControl
Licensed under Apache-2.0
-->
<robot xmlns:xacro="http://ros.org/wiki/xacro">

  <xacro:macro name="robotiq_2f85_gripper" params="parent_link prefix:=''">

    <!-- Robotiq Coupler -->
    <link name="${prefix}robotiq_coupler">
      <visual>
        <geometry>
          <mesh filename="package://ur5_robotiq_description/meshes/robotiq_85_coupler.stl" />
        </geometry>
        <material name="flat_black">
          <color rgba="0.1 0.1 0.1 1.0" />
        </material>
      </visual>
      <collision>
        <geometry>
          <mesh filename="package://ur5_robotiq_description/meshes/robotiq_85_coupler.stl" />
        </geometry>
      </collision>
      <inertial>
        <origin xyz="2.073e-05 1.45286e-03 -1.1049e-03" rpy="0 0 0" />
        <mass value="0.168" />
        <inertia ixx="6.69695624e-05" ixy="5.21511788e-09" ixz="-2.74383009e-08" 
                 iyy="7.85088161e-05" iyz="5.41105193e-07" izz="1.41819717e-04"/>
      </inertial>
    </link>

    <joint name="${prefix}robotiq_coupler_joint" type="fixed">
      <origin xyz="0 0 0.004" rpy="0 0 ${-pi/2.0}" />
      <parent link="${parent_link}"/>
      <child link="${prefix}robotiq_coupler"/>
    </joint>

    <!-- Robotiq Base -->
    <link name="${prefix}robotiq_85_base_link">
      <visual>
        <geometry>
          <mesh filename="package://ur5_robotiq_description/meshes/visual/robotiq_85_base_link.dae"/>
        </geometry>
      </visual>
      <collision>
        <geometry>
          <mesh filename="package://ur5_robotiq_description/meshes/collision/robotiq_85_base_link.stl"/>
        </geometry>
      </collision>
      <inertial>
        <mass value="0.636951" />
        <origin xyz="0.0 0.0 0.0" />
        <inertia ixx="0.000380" ixy="0.000000" ixz="0.000000"
                 iyx="0.000000" iyy="0.001110" iyz="0.000000"
                 izx="0.000000" izy="0.000000" izz="0.001171" />
      </inertial>
    </link>

    <joint name="${prefix}robotiq_85_base_joint" type="fixed">
      <origin xyz="0 0 0.004" rpy="0 ${-pi/2} ${pi}"/>
      <parent link="${prefix}robotiq_coupler"/>
      <child link="${prefix}robotiq_85_base_link"/>
    </joint>

    <!-- Left Knuckle -->
    <link name="${prefix}robotiq_85_left_knuckle_link">
      <visual>
        <geometry>
          <mesh filename="package://ur5_robotiq_description/meshes/visual/robotiq_85_knuckle_link.dae"/>
        </geometry>
      </visual>
      <collision>
        <geometry>
          <mesh filename="package://ur5_robotiq_description/meshes/collision/robotiq_85_knuckle_link.stl"/>
        </geometry>
      </collision>
      <inertial>
        <mass value="0.018491" />
        <origin xyz="0.0 0.0 0.0" />
        <inertia ixx="0.000009" ixy="-0.000001" ixz="0.000000"
                 iyx="-0.000001" iyy="0.000001" iyz="0.000000"
                 izx="0.000000" izy="0.000000" izz="0.000010" />
      </inertial>
    </link>

    <joint name="${prefix}robotiq_85_left_knuckle_joint" type="revolute">
      <parent link="${prefix}robotiq_85_base_link"/>
      <child link="${prefix}robotiq_85_left_knuckle_link"/>
      <axis xyz="0 0 1"/>
      <origin rpy="${pi} 0.0 0.0" xyz="0.05490451627 0.03060114443 0.0"/>
      <limit lower="0.0" upper="0.80285" velocity="0.5" effort="1000"/>
    </joint>

    <!-- Right Knuckle (mimic left) -->
    <link name="${prefix}robotiq_85_right_knuckle_link">
      <visual>
        <geometry>
          <mesh filename="package://ur5_robotiq_description/meshes/visual/robotiq_85_knuckle_link.dae"/>
        </geometry>
      </visual>
      <collision>
        <geometry>
          <mesh filename="package://ur5_robotiq_description/meshes/collision/robotiq_85_knuckle_link.stl"/>
        </geometry>
      </collision>
      <inertial>
        <mass value="0.018491" />
        <origin xyz="0.0 0.0 0.0" />
        <inertia ixx="0.000009" ixy="-0.000001" ixz="0.000000"
                 iyx="-0.000001" iyy="0.000001" iyz="0.000000"
                 izx="0.000000" izy="0.000000" izz="0.000010" />
      </inertial>
    </link>

    <joint name="${prefix}robotiq_85_right_knuckle_joint" type="revolute">
      <parent link="${prefix}robotiq_85_base_link"/>
      <child link="${prefix}robotiq_85_right_knuckle_link"/>
      <axis xyz="0 0 1"/>
      <origin rpy="0.0 0.0 0.0" xyz="0.05490451627 -0.03060114443 0.0"/>
      <limit lower="0.0" upper="0.80285" velocity="0.5" effort="1000"/>
      <mimic joint="${prefix}robotiq_85_left_knuckle_joint"/>
    </joint>

    <!-- Left Finger -->
    <link name="${prefix}robotiq_85_left_finger_link">
      <visual>
        <geometry>
          <mesh filename="package://ur5_robotiq_description/meshes/visual/robotiq_85_finger_link.dae"/>
        </geometry>
      </visual>
      <collision>
        <geometry>
          <mesh filename="package://ur5_robotiq_description/meshes/collision/robotiq_85_finger_link.stl"/>
        </geometry>
      </collision>
      <inertial>
        <mass value="0.027309" />
        <origin xyz="0.0 0.0 0.0" />
        <inertia ixx="0.000003" ixy="-0.000002" ixz="0.000000"
                 iyx="-0.000002" iyy="0.000021" iyz="0.000000"
                 izx="0.000000" izy="0.000000" izz="0.000020" />
      </inertial>
    </link>

    <joint name="${prefix}robotiq_85_left_finger_joint" type="fixed">
      <parent link="${prefix}robotiq_85_left_knuckle_link"/>
      <child link="${prefix}robotiq_85_left_finger_link"/>
      <origin xyz="-0.00408552455 -0.03148604435 0.0" rpy="0 0 0" />
    </joint>

    <!-- Right Finger -->
    <link name="${prefix}robotiq_85_right_finger_link">
      <visual>
        <geometry>
          <mesh filename="package://ur5_robotiq_description/meshes/visual/robotiq_85_finger_link.dae"/>
        </geometry>
      </visual>
      <collision>
        <geometry>
          <mesh filename="package://ur5_robotiq_description/meshes/collision/robotiq_85_finger_link.stl"/>
        </geometry>
      </collision>
      <inertial>
        <mass value="0.027309" />
        <origin xyz="0.0 0.0 0.0" />
        <inertia ixx="0.000003" ixy="-0.000002" ixz="0.000000"
                 iyx="-0.000002" iyy="0.000021" iyz="0.000000"
                 izx="0.000000" izy="0.000000" izz="0.000020" />
      </inertial>
    </link>

    <joint name="${prefix}robotiq_85_right_finger_joint" type="fixed">
      <parent link="${prefix}robotiq_85_right_knuckle_link"/>
      <child link="${prefix}robotiq_85_right_finger_link"/>
      <origin xyz="-0.00408552455 -0.03148604435 0.0" rpy="0 0 0" />
    </joint>

    <!-- Left Inner Knuckle -->
    <link name="${prefix}robotiq_85_left_inner_knuckle_link">
      <visual>
        <geometry>
          <mesh filename="package://ur5_robotiq_description/meshes/visual/robotiq_85_inner_knuckle_link.dae"/>
        </geometry>
      </visual>
      <collision>
        <geometry>
          <mesh filename="package://ur5_robotiq_description/meshes/collision/robotiq_85_inner_knuckle_link.stl"/>
        </geometry>
      </collision>
      <inertial>
        <mass value="0.029951" />
        <origin xyz="0.0 0.0 0.0" />
        <inertia ixx="0.000039" ixy="0.000000" ixz="0.000000"
                 iyx="0.000000" iyy="0.000005" iyz="0.000000"
                 izx="0.000000" izy="0.000000" izz="0.000035" />
      </inertial>
    </link>

    <joint name="${prefix}robotiq_85_left_inner_knuckle_joint" type="revolute">
      <parent link="${prefix}robotiq_85_base_link"/>
      <child link="${prefix}robotiq_85_left_inner_knuckle_link"/>
      <axis xyz="0 0 1"/>
      <origin xyz="0.06142 0.0127 0" rpy="${pi} 0.0 0.0" />
      <limit lower="0.0" upper="0.80285" velocity="0.5" effort="1000"/>
      <mimic joint="${prefix}robotiq_85_left_knuckle_joint"/>
    </joint>

    <!-- Right Inner Knuckle -->
    <link name="${prefix}robotiq_85_right_inner_knuckle_link">
      <visual>
        <geometry>
          <mesh filename="package://ur5_robotiq_description/meshes/visual/robotiq_85_inner_knuckle_link.dae"/>
        </geometry>
      </visual>
      <collision>
        <geometry>
          <mesh filename="package://ur5_robotiq_description/meshes/collision/robotiq_85_inner_knuckle_link.stl"/>
        </geometry>
      </collision>
      <inertial>
        <mass value="0.029951" />
        <origin xyz="0.0 0.0 0.0" />
        <inertia ixx="0.000039" ixy="0.000000" ixz="0.000000"
                 iyx="0.000000" iyy="0.000005" iyz="0.000000"
                 izx="0.000000" izy="0.000000" izz="0.000035" />
      </inertial>
    </link>

    <joint name="${prefix}robotiq_85_right_inner_knuckle_joint" type="revolute">
      <parent link="${prefix}robotiq_85_base_link"/>
      <child link="${prefix}robotiq_85_right_inner_knuckle_link"/>
      <axis xyz="0 0 1"/>
      <origin xyz="0.06142 -0.0127 0" rpy="0 0 0"/>
      <limit lower="0.0" upper="0.80285" velocity="0.5" effort="1000"/>
      <mimic joint="${prefix}robotiq_85_left_knuckle_joint"/>
    </joint>

    <!-- Left Finger Tip -->
    <link name="${prefix}robotiq_85_left_finger_tip_link">
      <visual>
        <geometry>
          <mesh filename="package://ur5_robotiq_description/meshes/visual/robotiq_85_finger_tip_link.dae"/>
        </geometry>
      </visual>
      <collision>
        <geometry>
          <mesh filename="package://ur5_robotiq_description/meshes/collision/robotiq_85_finger_tip_link.stl"/>
        </geometry>
      </collision>
      <inertial>
        <mass value="0.019555" />
        <origin xyz="0.0 0.0 0.0" />
        <inertia ixx="0.000002" ixy="0.000000" ixz="0.000000"
                 iyx="0.000000" iyy="0.000005" iyz="0.000000"
                 izx="0.000000" izy="0.000000" izz="0.000006" />
      </inertial>
    </link> 

    <joint name="${prefix}robotiq_85_left_finger_tip_joint" type="revolute">
      <parent link="${prefix}robotiq_85_left_inner_knuckle_link"/>
      <child link="${prefix}robotiq_85_left_finger_tip_link"/>
      <axis xyz="0 0 1"/>
      <origin xyz="0.04303959807 -0.03759940821 0.0" rpy="0.0 0.0 0.0"/>
      <limit lower="-0.80285" upper="0.0" velocity="0.5" effort="1000"/>
      <mimic joint="${prefix}robotiq_85_left_knuckle_joint" multiplier="-1"/>
    </joint>

    <!-- Right Finger Tip -->
    <link name="${prefix}robotiq_85_right_finger_tip_link">
      <visual>
        <geometry>
          <mesh filename="package://ur5_robotiq_description/meshes/visual/robotiq_85_finger_tip_link.dae"/>
        </geometry>
      </visual>
      <collision>
        <geometry>
          <mesh filename="package://ur5_robotiq_description/meshes/collision/robotiq_85_finger_tip_link.stl"/>
        </geometry>
      </collision>
      <inertial>
        <mass value="0.019555" />
        <origin xyz="0.0 0.0 0.0" />
        <inertia ixx="0.000002" ixy="0.000000" ixz="0.000000"
                 iyx="0.000000" iyy="0.000005" iyz="0.000000"
                 izx="0.000000" izy="0.000000" izz="0.000006" />
      </inertial>
    </link>

    <joint name="${prefix}robotiq_85_right_finger_tip_joint" type="revolute">
      <parent link="${prefix}robotiq_85_right_inner_knuckle_link"/>
      <child link="${prefix}robotiq_85_right_finger_tip_link"/>
      <axis xyz="0 0 1"/>
      <origin rpy="0.0 0.0 0.0" xyz="0.04303959807 -0.03759940821 0.0"/>
      <limit lower="-0.80285" upper="0.0" velocity="0.5" effort="1000"/>
      <mimic joint="${prefix}robotiq_85_left_knuckle_joint" multiplier="-1"/>
    </joint>

    <!-- Tool Center Point (TCP) -->
    <link name="${prefix}gripper_tcp"/>
    
    <joint name="${prefix}gripper_tcp_joint" type="fixed">
      <origin xyz="0.128 0.0 0.0" rpy="0 0 0"/>
      <parent link="${prefix}robotiq_85_base_link"/>
      <child link="${prefix}gripper_tcp"/>
    </joint>

  </xacro:macro>

</robot>
